2024-12-16 11:11:45 â€” INFO â€” Running with edr=0.16.1
2024-12-16 11:11:45 â€” INFO â€” Installing packages for edr internal dbt package...
2024-12-16 11:11:45 â€” INFO â€” Running dbt command --log-format json deps --project-dir /Users/emif/Documents/mutt/dbt-elementary-test-lab/.venv/lib/python3.10/site-packages/elementary/monitor/dbt_project
2024-12-16 11:11:47 â€” DEBUG â€” Running dbt command --log-format json run-operation elementary.log_macro_results --args {"macro_name": "elementary_cli.get_latest_invocation", "macro_args": {}} --project-dir /Users/emif/Documents/mutt/dbt-elementary-test-lab/.venv/lib/python3.10/site-packages/elementary/monitor/dbt_project
[31;20m2024-12-16 11:11:47 â€” ERROR â€” Unable to get the latest invocation: Failed to run dbt command.
Path '/Users/emif/.dbt' does not exist.[0m
2024-12-16 11:11:47 â€” DEBUG â€” Running dbt command --log-format json run-operation elementary.log_macro_results --args {"macro_name": "elementary_cli.get_adapter_type_and_unique_id", "macro_args": {}} --project-dir /Users/emif/Documents/mutt/dbt-elementary-test-lab/.venv/lib/python3.10/site-packages/elementary/monitor/dbt_project
2024-12-16 11:11:47 â€” DEBUG â€” Could not get warehouse info.
Traceback (most recent call last):
  File "/Users/emif/Documents/mutt/dbt-elementary-test-lab/.venv/lib/python3.10/site-packages/elementary/monitor/data_monitoring/data_monitoring.py", line 140, in _get_warehouse_info
    self.internal_dbt_runner.run_operation(
  File "/Users/emif/Documents/mutt/dbt-elementary-test-lab/.venv/lib/python3.10/site-packages/elementary/clients/dbt/command_line_dbt_runner.py", line 177, in run_operation
    result = self._run_command(
  File "/Users/emif/Documents/mutt/dbt-elementary-test-lab/.venv/lib/python3.10/site-packages/elementary/clients/dbt/command_line_dbt_runner.py", line 114, in _run_command
    result = self._inner_run_command(
  File "/Users/emif/Documents/mutt/dbt-elementary-test-lab/.venv/lib/python3.10/site-packages/elementary/clients/dbt/api_dbt_runner.py", line 53, in _inner_run_command
    raise DbtCommandError(
elementary.exceptions.exceptions.DbtCommandError: Failed to run dbt command.
Path '/Users/emif/.dbt' does not exist.
2024-12-16 11:11:47 â€” DEBUG â€” Running dbt command --log-format json run-operation elementary.log_macro_results --args {"macro_name": "elementary_cli.get_elementary_database_and_schema", "macro_args": {}} --project-dir /Users/emif/Documents/mutt/dbt-elementary-test-lab/.venv/lib/python3.10/site-packages/elementary/monitor/dbt_project
[31;20m2024-12-16 11:11:47 â€” ERROR â€” Failed to parse Elementary's database and schema.[0m
2024-12-16 11:11:47 â€” INFO â€” Running dbt command --log-format json run-operation elementary.log_macro_results --args {"macro_name": "elementary_cli.get_test_results", "macro_args": {"days_back": 7, "invocations_per_test": 720, "disable_passed_test_metrics": false}} --project-dir /Users/emif/Documents/mutt/dbt-elementary-test-lab/.venv/lib/python3.10/site-packages/elementary/monitor/dbt_project
[31;20m2024-12-16 11:11:47 â€” ERROR â€” Could not generate the report - Error: Failed to run dbt command.
Path '/Users/emif/.dbt' does not exist.
Please reach out to our community for help with this issue.[0m
Traceback (most recent call last):
  File "/Users/emif/Documents/mutt/dbt-elementary-test-lab/.venv/lib/python3.10/site-packages/elementary/monitor/api/report/report.py", line 50, in get_report_data
    tests_api = TestsAPI(
  File "/Users/emif/Documents/mutt/dbt-elementary-test-lab/.venv/lib/python3.10/site-packages/elementary/monitor/api/tests/tests.py", line 43, in __init__
    self.test_results_db_rows = self._get_test_results_db_rows(
  File "/Users/emif/Documents/mutt/dbt-elementary-test-lab/.venv/lib/python3.10/site-packages/elementary/monitor/api/tests/tests.py", line 55, in _get_test_results_db_rows
    return self.tests_fetcher.get_all_test_results_db_rows(
  File "/Users/emif/Documents/mutt/dbt-elementary-test-lab/.venv/lib/python3.10/site-packages/elementary/monitor/fetchers/tests/tests.py", line 25, in get_all_test_results_db_rows
    run_operation_response = self.dbt_runner.run_operation(
  File "/Users/emif/Documents/mutt/dbt-elementary-test-lab/.venv/lib/python3.10/site-packages/elementary/clients/dbt/command_line_dbt_runner.py", line 177, in run_operation
    result = self._run_command(
  File "/Users/emif/Documents/mutt/dbt-elementary-test-lab/.venv/lib/python3.10/site-packages/elementary/clients/dbt/command_line_dbt_runner.py", line 114, in _run_command
    result = self._inner_run_command(
  File "/Users/emif/Documents/mutt/dbt-elementary-test-lab/.venv/lib/python3.10/site-packages/elementary/clients/dbt/api_dbt_runner.py", line 53, in _inner_run_command
    raise DbtCommandError(
elementary.exceptions.exceptions.DbtCommandError: Failed to run dbt command.
Path '/Users/emif/.dbt' does not exist.
2024-12-16 11:25:40 â€” INFO â€” Running with edr=0.16.1
2024-12-16 11:25:40 â€” DEBUG â€” Running dbt command --log-format json run-operation elementary.log_macro_results --args {"macro_name": "elementary_cli.get_latest_invocation", "macro_args": {}} --project-dir /Users/emif/Documents/mutt/dbt-elementary-test-lab/.venv/lib/python3.10/site-packages/elementary/monitor/dbt_project
[31;20m2024-12-16 11:25:40 â€” ERROR â€” Unable to get the latest invocation: Failed to run dbt command.
Path '/Users/emif/.dbt' does not exist.[0m
2024-12-16 11:25:40 â€” DEBUG â€” Running dbt command --log-format json run-operation elementary.log_macro_results --args {"macro_name": "elementary_cli.get_adapter_type_and_unique_id", "macro_args": {}} --project-dir /Users/emif/Documents/mutt/dbt-elementary-test-lab/.venv/lib/python3.10/site-packages/elementary/monitor/dbt_project
2024-12-16 11:25:40 â€” DEBUG â€” Could not get warehouse info.
Traceback (most recent call last):
  File "/Users/emif/Documents/mutt/dbt-elementary-test-lab/.venv/lib/python3.10/site-packages/elementary/monitor/data_monitoring/data_monitoring.py", line 140, in _get_warehouse_info
    self.internal_dbt_runner.run_operation(
  File "/Users/emif/Documents/mutt/dbt-elementary-test-lab/.venv/lib/python3.10/site-packages/elementary/clients/dbt/command_line_dbt_runner.py", line 177, in run_operation
    result = self._run_command(
  File "/Users/emif/Documents/mutt/dbt-elementary-test-lab/.venv/lib/python3.10/site-packages/elementary/clients/dbt/command_line_dbt_runner.py", line 114, in _run_command
    result = self._inner_run_command(
  File "/Users/emif/Documents/mutt/dbt-elementary-test-lab/.venv/lib/python3.10/site-packages/elementary/clients/dbt/api_dbt_runner.py", line 53, in _inner_run_command
    raise DbtCommandError(
elementary.exceptions.exceptions.DbtCommandError: Failed to run dbt command.
Path '/Users/emif/.dbt' does not exist.
2024-12-16 11:25:40 â€” DEBUG â€” Running dbt command --log-format json run-operation elementary.log_macro_results --args {"macro_name": "elementary_cli.get_elementary_database_and_schema", "macro_args": {}} --project-dir /Users/emif/Documents/mutt/dbt-elementary-test-lab/.venv/lib/python3.10/site-packages/elementary/monitor/dbt_project
[31;20m2024-12-16 11:25:40 â€” ERROR â€” Failed to parse Elementary's database and schema.[0m
2024-12-16 11:25:40 â€” INFO â€” Running dbt command --log-format json run-operation elementary.log_macro_results --args {"macro_name": "elementary_cli.get_test_results", "macro_args": {"days_back": 7, "invocations_per_test": 720, "disable_passed_test_metrics": false}} --project-dir /Users/emif/Documents/mutt/dbt-elementary-test-lab/.venv/lib/python3.10/site-packages/elementary/monitor/dbt_project
[31;20m2024-12-16 11:25:40 â€” ERROR â€” Could not generate the report - Error: Failed to run dbt command.
Path '/Users/emif/.dbt' does not exist.
Please reach out to our community for help with this issue.[0m
Traceback (most recent call last):
  File "/Users/emif/Documents/mutt/dbt-elementary-test-lab/.venv/lib/python3.10/site-packages/elementary/monitor/api/report/report.py", line 50, in get_report_data
    tests_api = TestsAPI(
  File "/Users/emif/Documents/mutt/dbt-elementary-test-lab/.venv/lib/python3.10/site-packages/elementary/monitor/api/tests/tests.py", line 43, in __init__
    self.test_results_db_rows = self._get_test_results_db_rows(
  File "/Users/emif/Documents/mutt/dbt-elementary-test-lab/.venv/lib/python3.10/site-packages/elementary/monitor/api/tests/tests.py", line 55, in _get_test_results_db_rows
    return self.tests_fetcher.get_all_test_results_db_rows(
  File "/Users/emif/Documents/mutt/dbt-elementary-test-lab/.venv/lib/python3.10/site-packages/elementary/monitor/fetchers/tests/tests.py", line 25, in get_all_test_results_db_rows
    run_operation_response = self.dbt_runner.run_operation(
  File "/Users/emif/Documents/mutt/dbt-elementary-test-lab/.venv/lib/python3.10/site-packages/elementary/clients/dbt/command_line_dbt_runner.py", line 177, in run_operation
    result = self._run_command(
  File "/Users/emif/Documents/mutt/dbt-elementary-test-lab/.venv/lib/python3.10/site-packages/elementary/clients/dbt/command_line_dbt_runner.py", line 114, in _run_command
    result = self._inner_run_command(
  File "/Users/emif/Documents/mutt/dbt-elementary-test-lab/.venv/lib/python3.10/site-packages/elementary/clients/dbt/api_dbt_runner.py", line 53, in _inner_run_command
    raise DbtCommandError(
elementary.exceptions.exceptions.DbtCommandError: Failed to run dbt command.
Path '/Users/emif/.dbt' does not exist.
2024-12-16 11:27:28 â€” INFO â€” Running with edr=0.16.1
2024-12-16 11:27:28 â€” DEBUG â€” Running dbt command --log-format json run-operation elementary.log_macro_results --args {"macro_name": "elementary_cli.get_latest_invocation", "macro_args": {}} --project-dir /Users/emif/Documents/mutt/dbt-elementary-test-lab/.venv/lib/python3.10/site-packages/elementary/monitor/dbt_project
[31;20m2024-12-16 11:27:29 â€” ERROR â€” Unable to get the latest invocation: Failed to run dbt command.
Runtime Error
  Could not find profile named 'elementary'[0m
2024-12-16 11:27:29 â€” DEBUG â€” Running dbt command --log-format json run-operation elementary.log_macro_results --args {"macro_name": "elementary_cli.get_adapter_type_and_unique_id", "macro_args": {}} --project-dir /Users/emif/Documents/mutt/dbt-elementary-test-lab/.venv/lib/python3.10/site-packages/elementary/monitor/dbt_project
2024-12-16 11:27:29 â€” DEBUG â€” Could not get warehouse info.
Traceback (most recent call last):
  File "/Users/emif/Documents/mutt/dbt-elementary-test-lab/.venv/lib/python3.10/site-packages/elementary/monitor/data_monitoring/data_monitoring.py", line 140, in _get_warehouse_info
    self.internal_dbt_runner.run_operation(
  File "/Users/emif/Documents/mutt/dbt-elementary-test-lab/.venv/lib/python3.10/site-packages/elementary/clients/dbt/command_line_dbt_runner.py", line 177, in run_operation
    result = self._run_command(
  File "/Users/emif/Documents/mutt/dbt-elementary-test-lab/.venv/lib/python3.10/site-packages/elementary/clients/dbt/command_line_dbt_runner.py", line 114, in _run_command
    result = self._inner_run_command(
  File "/Users/emif/Documents/mutt/dbt-elementary-test-lab/.venv/lib/python3.10/site-packages/elementary/clients/dbt/api_dbt_runner.py", line 53, in _inner_run_command
    raise DbtCommandError(
elementary.exceptions.exceptions.DbtCommandError: Failed to run dbt command.
Runtime Error
  Could not find profile named 'elementary'
2024-12-16 11:27:29 â€” DEBUG â€” Running dbt command --log-format json run-operation elementary.log_macro_results --args {"macro_name": "elementary_cli.get_elementary_database_and_schema", "macro_args": {}} --project-dir /Users/emif/Documents/mutt/dbt-elementary-test-lab/.venv/lib/python3.10/site-packages/elementary/monitor/dbt_project
[31;20m2024-12-16 11:27:30 â€” ERROR â€” Failed to parse Elementary's database and schema.[0m
2024-12-16 11:27:30 â€” INFO â€” Running dbt command --log-format json run-operation elementary.log_macro_results --args {"macro_name": "elementary_cli.get_test_results", "macro_args": {"days_back": 7, "invocations_per_test": 720, "disable_passed_test_metrics": false}} --project-dir /Users/emif/Documents/mutt/dbt-elementary-test-lab/.venv/lib/python3.10/site-packages/elementary/monitor/dbt_project
[31;20m2024-12-16 11:27:30 â€” ERROR â€” Could not generate the report - Error: Failed to run dbt command.
Runtime Error
  Could not find profile named 'elementary'
Please reach out to our community for help with this issue.[0m
Traceback (most recent call last):
  File "/Users/emif/Documents/mutt/dbt-elementary-test-lab/.venv/lib/python3.10/site-packages/elementary/monitor/api/report/report.py", line 50, in get_report_data
    tests_api = TestsAPI(
  File "/Users/emif/Documents/mutt/dbt-elementary-test-lab/.venv/lib/python3.10/site-packages/elementary/monitor/api/tests/tests.py", line 43, in __init__
    self.test_results_db_rows = self._get_test_results_db_rows(
  File "/Users/emif/Documents/mutt/dbt-elementary-test-lab/.venv/lib/python3.10/site-packages/elementary/monitor/api/tests/tests.py", line 55, in _get_test_results_db_rows
    return self.tests_fetcher.get_all_test_results_db_rows(
  File "/Users/emif/Documents/mutt/dbt-elementary-test-lab/.venv/lib/python3.10/site-packages/elementary/monitor/fetchers/tests/tests.py", line 25, in get_all_test_results_db_rows
    run_operation_response = self.dbt_runner.run_operation(
  File "/Users/emif/Documents/mutt/dbt-elementary-test-lab/.venv/lib/python3.10/site-packages/elementary/clients/dbt/command_line_dbt_runner.py", line 177, in run_operation
    result = self._run_command(
  File "/Users/emif/Documents/mutt/dbt-elementary-test-lab/.venv/lib/python3.10/site-packages/elementary/clients/dbt/command_line_dbt_runner.py", line 114, in _run_command
    result = self._inner_run_command(
  File "/Users/emif/Documents/mutt/dbt-elementary-test-lab/.venv/lib/python3.10/site-packages/elementary/clients/dbt/api_dbt_runner.py", line 53, in _inner_run_command
    raise DbtCommandError(
elementary.exceptions.exceptions.DbtCommandError: Failed to run dbt command.
Runtime Error
  Could not find profile named 'elementary'
2024-12-16 11:29:09 â€” INFO â€” Running with edr=0.16.1
2024-12-16 11:29:09 â€” DEBUG â€” Running dbt command --log-format json run-operation elementary.log_macro_results --args {"macro_name": "elementary_cli.get_latest_invocation", "macro_args": {}} --project-dir /Users/emif/Documents/mutt/dbt-elementary-test-lab/.venv/lib/python3.10/site-packages/elementary/monitor/dbt_project
2024-12-16 11:29:13 â€” DEBUG â€” Result bytes size for command '['--log-format', 'json', 'run-operation', 'elementary.log_macro_results', '--args', '{"macro_name": "elementary_cli.get_latest_invocation", "macro_args": {}}', '--project-dir', '/Users/emif/Documents/mutt/dbt-elementary-test-lab/.venv/lib/python3.10/site-packages/elementary/monitor/dbt_project']' is 2494
2024-12-16 11:29:13 â€” DEBUG â€” Running dbt command --log-format json run-operation elementary.log_macro_results --args {"macro_name": "elementary_cli.get_adapter_type_and_unique_id", "macro_args": {}} --project-dir /Users/emif/Documents/mutt/dbt-elementary-test-lab/.venv/lib/python3.10/site-packages/elementary/monitor/dbt_project
2024-12-16 11:29:13 â€” DEBUG â€” Result bytes size for command '['--log-format', 'json', 'run-operation', 'elementary.log_macro_results', '--args', '{"macro_name": "elementary_cli.get_adapter_type_and_unique_id", "macro_args": {}}', '--project-dir', '/Users/emif/Documents/mutt/dbt-elementary-test-lab/.venv/lib/python3.10/site-packages/elementary/monitor/dbt_project']' is 456
2024-12-16 11:29:13 â€” INFO â€” edr (0.16.1) and Elementary's dbt package (0.16.2) are compatible.
2024-12-16 11:29:13 â€” DEBUG â€” Running dbt command --log-format json run-operation elementary.log_macro_results --args {"macro_name": "elementary_cli.get_elementary_database_and_schema", "macro_args": {}} --project-dir /Users/emif/Documents/mutt/dbt-elementary-test-lab/.venv/lib/python3.10/site-packages/elementary/monitor/dbt_project
2024-12-16 11:29:14 â€” DEBUG â€” Result bytes size for command '['--log-format', 'json', 'run-operation', 'elementary.log_macro_results', '--args', '{"macro_name": "elementary_cli.get_elementary_database_and_schema", "macro_args": {}}', '--project-dir', '/Users/emif/Documents/mutt/dbt-elementary-test-lab/.venv/lib/python3.10/site-packages/elementary/monitor/dbt_project']' is 448
2024-12-16 11:29:14 â€” INFO â€” Elementary's database and schema: '"elementary.elementary"'
2024-12-16 11:29:14 â€” INFO â€” Running dbt command --log-format json run-operation elementary.log_macro_results --args {"macro_name": "elementary_cli.get_test_results", "macro_args": {"days_back": 7, "invocations_per_test": 720, "disable_passed_test_metrics": false}} --project-dir /Users/emif/Documents/mutt/dbt-elementary-test-lab/.venv/lib/python3.10/site-packages/elementary/monitor/dbt_project
2024-12-16 11:29:15 â€” DEBUG â€” Result bytes size for command '['--log-format', 'json', 'run-operation', 'elementary.log_macro_results', '--args', '{"macro_name": "elementary_cli.get_test_results", "macro_args": {"days_back": 7, "invocations_per_test": 720, "disable_passed_test_metrics": false}}', '--project-dir', '/Users/emif/Documents/mutt/dbt-elementary-test-lab/.venv/lib/python3.10/site-packages/elementary/monitor/dbt_project']' is 483292
2024-12-16 11:29:15 â€” INFO â€” Running dbt command --log-format json run-operation elementary.log_macro_results --args {"macro_name": "elementary_cli.get_source_freshness_results", "macro_args": {"days_back": 7, "invocations_per_test": 720}} --project-dir /Users/emif/Documents/mutt/dbt-elementary-test-lab/.venv/lib/python3.10/site-packages/elementary/monitor/dbt_project
2024-12-16 11:29:15 â€” DEBUG â€” Result bytes size for command '['--log-format', 'json', 'run-operation', 'elementary.log_macro_results', '--args', '{"macro_name": "elementary_cli.get_source_freshness_results", "macro_args": {"days_back": 7, "invocations_per_test": 720}}', '--project-dir', '/Users/emif/Documents/mutt/dbt-elementary-test-lab/.venv/lib/python3.10/site-packages/elementary/monitor/dbt_project']' is 402
2024-12-16 11:29:15 â€” INFO â€” Running dbt command --log-format json run-operation elementary.log_macro_results --args {"macro_name": "elementary_cli.get_models", "macro_args": {"exclude_elementary": true}} --project-dir /Users/emif/Documents/mutt/dbt-elementary-test-lab/.venv/lib/python3.10/site-packages/elementary/monitor/dbt_project
2024-12-16 11:29:16 â€” DEBUG â€” Result bytes size for command '['--log-format', 'json', 'run-operation', 'elementary.log_macro_results', '--args', '{"macro_name": "elementary_cli.get_models", "macro_args": {"exclude_elementary": true}}', '--project-dir', '/Users/emif/Documents/mutt/dbt-elementary-test-lab/.venv/lib/python3.10/site-packages/elementary/monitor/dbt_project']' is 5140
2024-12-16 11:29:16 â€” INFO â€” Running dbt command --log-format json run-operation elementary.log_macro_results --args {"macro_name": "elementary_cli.get_sources", "macro_args": {}} --project-dir /Users/emif/Documents/mutt/dbt-elementary-test-lab/.venv/lib/python3.10/site-packages/elementary/monitor/dbt_project
2024-12-16 11:29:17 â€” DEBUG â€” Result bytes size for command '['--log-format', 'json', 'run-operation', 'elementary.log_macro_results', '--args', '{"macro_name": "elementary_cli.get_sources", "macro_args": {}}', '--project-dir', '/Users/emif/Documents/mutt/dbt-elementary-test-lab/.venv/lib/python3.10/site-packages/elementary/monitor/dbt_project']' is 402
2024-12-16 11:29:17 â€” INFO â€” Running dbt command --log-format json run-operation elementary.log_macro_results --args {"macro_name": "elementary_cli.get_exposures", "macro_args": {}} --project-dir /Users/emif/Documents/mutt/dbt-elementary-test-lab/.venv/lib/python3.10/site-packages/elementary/monitor/dbt_project
2024-12-16 11:29:17 â€” DEBUG â€” Result bytes size for command '['--log-format', 'json', 'run-operation', 'elementary.log_macro_results', '--args', '{"macro_name": "elementary_cli.get_exposures", "macro_args": {}}', '--project-dir', '/Users/emif/Documents/mutt/dbt-elementary-test-lab/.venv/lib/python3.10/site-packages/elementary/monitor/dbt_project']' is 402
2024-12-16 11:29:17 â€” INFO â€” Running dbt command --log-format json run-operation elementary.log_macro_results --args {"macro_name": "elementary_cli.get_singular_tests", "macro_args": {}} --project-dir /Users/emif/Documents/mutt/dbt-elementary-test-lab/.venv/lib/python3.10/site-packages/elementary/monitor/dbt_project
2024-12-16 11:29:18 â€” DEBUG â€” Result bytes size for command '['--log-format', 'json', 'run-operation', 'elementary.log_macro_results', '--args', '{"macro_name": "elementary_cli.get_singular_tests", "macro_args": {}}', '--project-dir', '/Users/emif/Documents/mutt/dbt-elementary-test-lab/.venv/lib/python3.10/site-packages/elementary/monitor/dbt_project']' is 402
2024-12-16 11:29:18 â€” INFO â€” Running dbt command --log-format json run-operation elementary.log_macro_results --args {"macro_name": "elementary_cli.get_models_runs", "macro_args": {"days_back": 7, "exclude_elementary": true}} --project-dir /Users/emif/Documents/mutt/dbt-elementary-test-lab/.venv/lib/python3.10/site-packages/elementary/monitor/dbt_project
2024-12-16 11:29:19 â€” DEBUG â€” Result bytes size for command '['--log-format', 'json', 'run-operation', 'elementary.log_macro_results', '--args', '{"macro_name": "elementary_cli.get_models_runs", "macro_args": {"days_back": 7, "exclude_elementary": true}}', '--project-dir', '/Users/emif/Documents/mutt/dbt-elementary-test-lab/.venv/lib/python3.10/site-packages/elementary/monitor/dbt_project']' is 52088
2024-12-16 11:29:19 â€” INFO â€” Running dbt command --log-format json run-operation elementary.log_macro_results --args {"macro_name": "elementary_cli.get_dbt_models_test_coverage", "macro_args": {}} --project-dir /Users/emif/Documents/mutt/dbt-elementary-test-lab/.venv/lib/python3.10/site-packages/elementary/monitor/dbt_project
2024-12-16 11:29:20 â€” DEBUG â€” Result bytes size for command '['--log-format', 'json', 'run-operation', 'elementary.log_macro_results', '--args', '{"macro_name": "elementary_cli.get_dbt_models_test_coverage", "macro_args": {}}', '--project-dir', '/Users/emif/Documents/mutt/dbt-elementary-test-lab/.venv/lib/python3.10/site-packages/elementary/monitor/dbt_project']' is 1242
2024-12-16 11:29:20 â€” INFO â€” Running dbt command --log-format json run-operation elementary.log_macro_results --args {"macro_name": "elementary_cli.get_nodes_depends_on_nodes", "macro_args": {"exclude_elementary": true}} --project-dir /Users/emif/Documents/mutt/dbt-elementary-test-lab/.venv/lib/python3.10/site-packages/elementary/monitor/dbt_project
2024-12-16 11:29:20 â€” DEBUG â€” Result bytes size for command '['--log-format', 'json', 'run-operation', 'elementary.log_macro_results', '--args', '{"macro_name": "elementary_cli.get_nodes_depends_on_nodes", "macro_args": {"exclude_elementary": true}}', '--project-dir', '/Users/emif/Documents/mutt/dbt-elementary-test-lab/.venv/lib/python3.10/site-packages/elementary/monitor/dbt_project']' is 2356
2024-12-16 11:29:20 â€” INFO â€” Running dbt command --log-format json run-operation elementary.log_macro_results --args {"macro_name": "elementary_cli.get_models_latest_invocation", "macro_args": {}} --project-dir /Users/emif/Documents/mutt/dbt-elementary-test-lab/.venv/lib/python3.10/site-packages/elementary/monitor/dbt_project
2024-12-16 11:29:21 â€” DEBUG â€” Result bytes size for command '['--log-format', 'json', 'run-operation', 'elementary.log_macro_results', '--args', '{"macro_name": "elementary_cli.get_models_latest_invocation", "macro_args": {}}', '--project-dir', '/Users/emif/Documents/mutt/dbt-elementary-test-lab/.venv/lib/python3.10/site-packages/elementary/monitor/dbt_project']' is 8442
2024-12-16 11:29:21 â€” INFO â€” Running dbt command --log-format json run-operation elementary.log_macro_results --args {"macro_name": "elementary_cli.get_models_latest_invocations_data", "macro_args": {}} --project-dir /Users/emif/Documents/mutt/dbt-elementary-test-lab/.venv/lib/python3.10/site-packages/elementary/monitor/dbt_project
2024-12-16 11:29:22 â€” DEBUG â€” Result bytes size for command '['--log-format', 'json', 'run-operation', 'elementary.log_macro_results', '--args', '{"macro_name": "elementary_cli.get_models_latest_invocations_data", "macro_args": {}}', '--project-dir', '/Users/emif/Documents/mutt/dbt-elementary-test-lab/.venv/lib/python3.10/site-packages/elementary/monitor/dbt_project']' is 828
2024-12-16 11:45:18 â€” INFO â€” Running with edr=0.16.1
2024-12-16 11:45:18 â€” DEBUG â€” Running dbt command --log-format json run-operation elementary.log_macro_results --args {"macro_name": "elementary_cli.get_latest_invocation", "macro_args": {}} --project-dir /Users/emif/Documents/mutt/dbt-elementary-test-lab/.venv/lib/python3.10/site-packages/elementary/monitor/dbt_project
[31;20m2024-12-16 11:45:18 â€” ERROR â€” Unable to get the latest invocation: Failed to run dbt command.
Path '/Users/emif/.dbt' does not exist.[0m
2024-12-16 11:45:18 â€” DEBUG â€” Running dbt command --log-format json run-operation elementary.log_macro_results --args {"macro_name": "elementary_cli.get_adapter_type_and_unique_id", "macro_args": {}} --project-dir /Users/emif/Documents/mutt/dbt-elementary-test-lab/.venv/lib/python3.10/site-packages/elementary/monitor/dbt_project
2024-12-16 11:45:18 â€” DEBUG â€” Could not get warehouse info.
Traceback (most recent call last):
  File "/Users/emif/Documents/mutt/dbt-elementary-test-lab/.venv/lib/python3.10/site-packages/elementary/monitor/data_monitoring/data_monitoring.py", line 140, in _get_warehouse_info
    self.internal_dbt_runner.run_operation(
  File "/Users/emif/Documents/mutt/dbt-elementary-test-lab/.venv/lib/python3.10/site-packages/elementary/clients/dbt/command_line_dbt_runner.py", line 177, in run_operation
    result = self._run_command(
  File "/Users/emif/Documents/mutt/dbt-elementary-test-lab/.venv/lib/python3.10/site-packages/elementary/clients/dbt/command_line_dbt_runner.py", line 114, in _run_command
    result = self._inner_run_command(
  File "/Users/emif/Documents/mutt/dbt-elementary-test-lab/.venv/lib/python3.10/site-packages/elementary/clients/dbt/api_dbt_runner.py", line 53, in _inner_run_command
    raise DbtCommandError(
elementary.exceptions.exceptions.DbtCommandError: Failed to run dbt command.
Path '/Users/emif/.dbt' does not exist.
2024-12-16 11:45:18 â€” DEBUG â€” Running dbt command --log-format json run-operation elementary.log_macro_results --args {"macro_name": "elementary_cli.get_elementary_database_and_schema", "macro_args": {}} --project-dir /Users/emif/Documents/mutt/dbt-elementary-test-lab/.venv/lib/python3.10/site-packages/elementary/monitor/dbt_project
[31;20m2024-12-16 11:45:18 â€” ERROR â€” Failed to parse Elementary's database and schema.[0m
2024-12-16 11:45:18 â€” INFO â€” Running dbt command --log-format json run-operation elementary.log_macro_results --args {"macro_name": "elementary_cli.get_test_results", "macro_args": {"days_back": 7, "invocations_per_test": 720, "disable_passed_test_metrics": false}} --project-dir /Users/emif/Documents/mutt/dbt-elementary-test-lab/.venv/lib/python3.10/site-packages/elementary/monitor/dbt_project
[31;20m2024-12-16 11:45:18 â€” ERROR â€” Could not generate the report - Error: Failed to run dbt command.
Path '/Users/emif/.dbt' does not exist.
Please reach out to our community for help with this issue.[0m
Traceback (most recent call last):
  File "/Users/emif/Documents/mutt/dbt-elementary-test-lab/.venv/lib/python3.10/site-packages/elementary/monitor/api/report/report.py", line 50, in get_report_data
    tests_api = TestsAPI(
  File "/Users/emif/Documents/mutt/dbt-elementary-test-lab/.venv/lib/python3.10/site-packages/elementary/monitor/api/tests/tests.py", line 43, in __init__
    self.test_results_db_rows = self._get_test_results_db_rows(
  File "/Users/emif/Documents/mutt/dbt-elementary-test-lab/.venv/lib/python3.10/site-packages/elementary/monitor/api/tests/tests.py", line 55, in _get_test_results_db_rows
    return self.tests_fetcher.get_all_test_results_db_rows(
  File "/Users/emif/Documents/mutt/dbt-elementary-test-lab/.venv/lib/python3.10/site-packages/elementary/monitor/fetchers/tests/tests.py", line 25, in get_all_test_results_db_rows
    run_operation_response = self.dbt_runner.run_operation(
  File "/Users/emif/Documents/mutt/dbt-elementary-test-lab/.venv/lib/python3.10/site-packages/elementary/clients/dbt/command_line_dbt_runner.py", line 177, in run_operation
    result = self._run_command(
  File "/Users/emif/Documents/mutt/dbt-elementary-test-lab/.venv/lib/python3.10/site-packages/elementary/clients/dbt/command_line_dbt_runner.py", line 114, in _run_command
    result = self._inner_run_command(
  File "/Users/emif/Documents/mutt/dbt-elementary-test-lab/.venv/lib/python3.10/site-packages/elementary/clients/dbt/api_dbt_runner.py", line 53, in _inner_run_command
    raise DbtCommandError(
elementary.exceptions.exceptions.DbtCommandError: Failed to run dbt command.
Path '/Users/emif/.dbt' does not exist.
2024-12-16 11:45:58 â€” INFO â€” Running with edr=0.16.1
2024-12-16 11:45:58 â€” DEBUG â€” Running dbt command --log-format json run-operation elementary.log_macro_results --args {"macro_name": "elementary_cli.get_latest_invocation", "macro_args": {}} --project-dir /Users/emif/Documents/mutt/dbt-elementary-test-lab/.venv/lib/python3.10/site-packages/elementary/monitor/dbt_project
[31;20m2024-12-16 11:45:58 â€” ERROR â€” Unable to get the latest invocation: Failed to run dbt command.
Path '/Users/emif/.dbt' does not exist.[0m
2024-12-16 11:45:58 â€” DEBUG â€” Running dbt command --log-format json run-operation elementary.log_macro_results --args {"macro_name": "elementary_cli.get_adapter_type_and_unique_id", "macro_args": {}} --project-dir /Users/emif/Documents/mutt/dbt-elementary-test-lab/.venv/lib/python3.10/site-packages/elementary/monitor/dbt_project
2024-12-16 11:45:58 â€” DEBUG â€” Could not get warehouse info.
Traceback (most recent call last):
  File "/Users/emif/Documents/mutt/dbt-elementary-test-lab/.venv/lib/python3.10/site-packages/elementary/monitor/data_monitoring/data_monitoring.py", line 140, in _get_warehouse_info
    self.internal_dbt_runner.run_operation(
  File "/Users/emif/Documents/mutt/dbt-elementary-test-lab/.venv/lib/python3.10/site-packages/elementary/clients/dbt/command_line_dbt_runner.py", line 177, in run_operation
    result = self._run_command(
  File "/Users/emif/Documents/mutt/dbt-elementary-test-lab/.venv/lib/python3.10/site-packages/elementary/clients/dbt/command_line_dbt_runner.py", line 114, in _run_command
    result = self._inner_run_command(
  File "/Users/emif/Documents/mutt/dbt-elementary-test-lab/.venv/lib/python3.10/site-packages/elementary/clients/dbt/api_dbt_runner.py", line 53, in _inner_run_command
    raise DbtCommandError(
elementary.exceptions.exceptions.DbtCommandError: Failed to run dbt command.
Path '/Users/emif/.dbt' does not exist.
2024-12-16 11:45:58 â€” DEBUG â€” Running dbt command --log-format json run-operation elementary.log_macro_results --args {"macro_name": "elementary_cli.get_elementary_database_and_schema", "macro_args": {}} --project-dir /Users/emif/Documents/mutt/dbt-elementary-test-lab/.venv/lib/python3.10/site-packages/elementary/monitor/dbt_project
[31;20m2024-12-16 11:45:58 â€” ERROR â€” Failed to parse Elementary's database and schema.[0m
2024-12-16 11:45:58 â€” INFO â€” Running dbt command --log-format json run-operation elementary.log_macro_results --args {"macro_name": "elementary_cli.get_test_results", "macro_args": {"days_back": 7, "invocations_per_test": 720, "disable_passed_test_metrics": false}} --project-dir /Users/emif/Documents/mutt/dbt-elementary-test-lab/.venv/lib/python3.10/site-packages/elementary/monitor/dbt_project
[31;20m2024-12-16 11:45:58 â€” ERROR â€” Could not generate the report - Error: Failed to run dbt command.
Path '/Users/emif/.dbt' does not exist.
Please reach out to our community for help with this issue.[0m
Traceback (most recent call last):
  File "/Users/emif/Documents/mutt/dbt-elementary-test-lab/.venv/lib/python3.10/site-packages/elementary/monitor/api/report/report.py", line 50, in get_report_data
    tests_api = TestsAPI(
  File "/Users/emif/Documents/mutt/dbt-elementary-test-lab/.venv/lib/python3.10/site-packages/elementary/monitor/api/tests/tests.py", line 43, in __init__
    self.test_results_db_rows = self._get_test_results_db_rows(
  File "/Users/emif/Documents/mutt/dbt-elementary-test-lab/.venv/lib/python3.10/site-packages/elementary/monitor/api/tests/tests.py", line 55, in _get_test_results_db_rows
    return self.tests_fetcher.get_all_test_results_db_rows(
  File "/Users/emif/Documents/mutt/dbt-elementary-test-lab/.venv/lib/python3.10/site-packages/elementary/monitor/fetchers/tests/tests.py", line 25, in get_all_test_results_db_rows
    run_operation_response = self.dbt_runner.run_operation(
  File "/Users/emif/Documents/mutt/dbt-elementary-test-lab/.venv/lib/python3.10/site-packages/elementary/clients/dbt/command_line_dbt_runner.py", line 177, in run_operation
    result = self._run_command(
  File "/Users/emif/Documents/mutt/dbt-elementary-test-lab/.venv/lib/python3.10/site-packages/elementary/clients/dbt/command_line_dbt_runner.py", line 114, in _run_command
    result = self._inner_run_command(
  File "/Users/emif/Documents/mutt/dbt-elementary-test-lab/.venv/lib/python3.10/site-packages/elementary/clients/dbt/api_dbt_runner.py", line 53, in _inner_run_command
    raise DbtCommandError(
elementary.exceptions.exceptions.DbtCommandError: Failed to run dbt command.
Path '/Users/emif/.dbt' does not exist.
2024-12-16 11:47:09 â€” INFO â€” Running with edr=0.16.1
2024-12-16 11:47:09 â€” DEBUG â€” Running dbt command --log-format json run-operation elementary.log_macro_results --args {"macro_name": "elementary_cli.get_latest_invocation", "macro_args": {}} --project-dir /Users/emif/Documents/mutt/dbt-elementary-test-lab/.venv/lib/python3.10/site-packages/elementary/monitor/dbt_project
[31;20m2024-12-16 11:47:09 â€” ERROR â€” Unable to get the latest invocation: Failed to run dbt command.
Path '/Users/emif/.dbt' does not exist.[0m
2024-12-16 11:47:09 â€” DEBUG â€” Running dbt command --log-format json run-operation elementary.log_macro_results --args {"macro_name": "elementary_cli.get_adapter_type_and_unique_id", "macro_args": {}} --project-dir /Users/emif/Documents/mutt/dbt-elementary-test-lab/.venv/lib/python3.10/site-packages/elementary/monitor/dbt_project
2024-12-16 11:47:09 â€” DEBUG â€” Could not get warehouse info.
Traceback (most recent call last):
  File "/Users/emif/Documents/mutt/dbt-elementary-test-lab/.venv/lib/python3.10/site-packages/elementary/monitor/data_monitoring/data_monitoring.py", line 140, in _get_warehouse_info
    self.internal_dbt_runner.run_operation(
  File "/Users/emif/Documents/mutt/dbt-elementary-test-lab/.venv/lib/python3.10/site-packages/elementary/clients/dbt/command_line_dbt_runner.py", line 177, in run_operation
    result = self._run_command(
  File "/Users/emif/Documents/mutt/dbt-elementary-test-lab/.venv/lib/python3.10/site-packages/elementary/clients/dbt/command_line_dbt_runner.py", line 114, in _run_command
    result = self._inner_run_command(
  File "/Users/emif/Documents/mutt/dbt-elementary-test-lab/.venv/lib/python3.10/site-packages/elementary/clients/dbt/api_dbt_runner.py", line 53, in _inner_run_command
    raise DbtCommandError(
elementary.exceptions.exceptions.DbtCommandError: Failed to run dbt command.
Path '/Users/emif/.dbt' does not exist.
2024-12-16 11:47:09 â€” DEBUG â€” Running dbt command --log-format json run-operation elementary.log_macro_results --args {"macro_name": "elementary_cli.get_elementary_database_and_schema", "macro_args": {}} --project-dir /Users/emif/Documents/mutt/dbt-elementary-test-lab/.venv/lib/python3.10/site-packages/elementary/monitor/dbt_project
[31;20m2024-12-16 11:47:09 â€” ERROR â€” Failed to parse Elementary's database and schema.[0m
2024-12-16 11:47:09 â€” INFO â€” Running dbt command --log-format json run-operation elementary.log_macro_results --args {"macro_name": "elementary_cli.get_test_results", "macro_args": {"days_back": 7, "invocations_per_test": 720, "disable_passed_test_metrics": false}} --project-dir /Users/emif/Documents/mutt/dbt-elementary-test-lab/.venv/lib/python3.10/site-packages/elementary/monitor/dbt_project
[31;20m2024-12-16 11:47:09 â€” ERROR â€” Could not generate the report - Error: Failed to run dbt command.
Path '/Users/emif/.dbt' does not exist.
Please reach out to our community for help with this issue.[0m
Traceback (most recent call last):
  File "/Users/emif/Documents/mutt/dbt-elementary-test-lab/.venv/lib/python3.10/site-packages/elementary/monitor/api/report/report.py", line 50, in get_report_data
    tests_api = TestsAPI(
  File "/Users/emif/Documents/mutt/dbt-elementary-test-lab/.venv/lib/python3.10/site-packages/elementary/monitor/api/tests/tests.py", line 43, in __init__
    self.test_results_db_rows = self._get_test_results_db_rows(
  File "/Users/emif/Documents/mutt/dbt-elementary-test-lab/.venv/lib/python3.10/site-packages/elementary/monitor/api/tests/tests.py", line 55, in _get_test_results_db_rows
    return self.tests_fetcher.get_all_test_results_db_rows(
  File "/Users/emif/Documents/mutt/dbt-elementary-test-lab/.venv/lib/python3.10/site-packages/elementary/monitor/fetchers/tests/tests.py", line 25, in get_all_test_results_db_rows
    run_operation_response = self.dbt_runner.run_operation(
  File "/Users/emif/Documents/mutt/dbt-elementary-test-lab/.venv/lib/python3.10/site-packages/elementary/clients/dbt/command_line_dbt_runner.py", line 177, in run_operation
    result = self._run_command(
  File "/Users/emif/Documents/mutt/dbt-elementary-test-lab/.venv/lib/python3.10/site-packages/elementary/clients/dbt/command_line_dbt_runner.py", line 114, in _run_command
    result = self._inner_run_command(
  File "/Users/emif/Documents/mutt/dbt-elementary-test-lab/.venv/lib/python3.10/site-packages/elementary/clients/dbt/api_dbt_runner.py", line 53, in _inner_run_command
    raise DbtCommandError(
elementary.exceptions.exceptions.DbtCommandError: Failed to run dbt command.
Path '/Users/emif/.dbt' does not exist.
2024-12-16 11:49:17 â€” INFO â€” Running with edr=0.16.1
2024-12-16 11:49:17 â€” DEBUG â€” Running dbt command --log-format json run-operation elementary.log_macro_results --args {"macro_name": "elementary_cli.get_latest_invocation", "macro_args": {}} --project-dir /Users/emif/Documents/mutt/dbt-elementary-test-lab/.venv/lib/python3.10/site-packages/elementary/monitor/dbt_project
[31;20m2024-12-16 11:49:17 â€” ERROR â€” Unable to get the latest invocation: Failed to run dbt command.
Path '/Users/emif/.dbt' does not exist.[0m
2024-12-16 11:49:17 â€” DEBUG â€” Running dbt command --log-format json run-operation elementary.log_macro_results --args {"macro_name": "elementary_cli.get_adapter_type_and_unique_id", "macro_args": {}} --project-dir /Users/emif/Documents/mutt/dbt-elementary-test-lab/.venv/lib/python3.10/site-packages/elementary/monitor/dbt_project
2024-12-16 11:49:17 â€” DEBUG â€” Could not get warehouse info.
Traceback (most recent call last):
  File "/Users/emif/Documents/mutt/dbt-elementary-test-lab/.venv/lib/python3.10/site-packages/elementary/monitor/data_monitoring/data_monitoring.py", line 140, in _get_warehouse_info
    self.internal_dbt_runner.run_operation(
  File "/Users/emif/Documents/mutt/dbt-elementary-test-lab/.venv/lib/python3.10/site-packages/elementary/clients/dbt/command_line_dbt_runner.py", line 177, in run_operation
    result = self._run_command(
  File "/Users/emif/Documents/mutt/dbt-elementary-test-lab/.venv/lib/python3.10/site-packages/elementary/clients/dbt/command_line_dbt_runner.py", line 114, in _run_command
    result = self._inner_run_command(
  File "/Users/emif/Documents/mutt/dbt-elementary-test-lab/.venv/lib/python3.10/site-packages/elementary/clients/dbt/api_dbt_runner.py", line 53, in _inner_run_command
    raise DbtCommandError(
elementary.exceptions.exceptions.DbtCommandError: Failed to run dbt command.
Path '/Users/emif/.dbt' does not exist.
2024-12-16 11:49:17 â€” DEBUG â€” Running dbt command --log-format json run-operation elementary.log_macro_results --args {"macro_name": "elementary_cli.get_elementary_database_and_schema", "macro_args": {}} --project-dir /Users/emif/Documents/mutt/dbt-elementary-test-lab/.venv/lib/python3.10/site-packages/elementary/monitor/dbt_project
[31;20m2024-12-16 11:49:17 â€” ERROR â€” Failed to parse Elementary's database and schema.[0m
2024-12-16 11:49:17 â€” INFO â€” Running dbt command --log-format json run-operation elementary.log_macro_results --args {"macro_name": "elementary_cli.get_test_results", "macro_args": {"days_back": 7, "invocations_per_test": 720, "disable_passed_test_metrics": false}} --project-dir /Users/emif/Documents/mutt/dbt-elementary-test-lab/.venv/lib/python3.10/site-packages/elementary/monitor/dbt_project
[31;20m2024-12-16 11:49:17 â€” ERROR â€” Could not generate the report - Error: Failed to run dbt command.
Path '/Users/emif/.dbt' does not exist.
Please reach out to our community for help with this issue.[0m
Traceback (most recent call last):
  File "/Users/emif/Documents/mutt/dbt-elementary-test-lab/.venv/lib/python3.10/site-packages/elementary/monitor/api/report/report.py", line 50, in get_report_data
    tests_api = TestsAPI(
  File "/Users/emif/Documents/mutt/dbt-elementary-test-lab/.venv/lib/python3.10/site-packages/elementary/monitor/api/tests/tests.py", line 43, in __init__
    self.test_results_db_rows = self._get_test_results_db_rows(
  File "/Users/emif/Documents/mutt/dbt-elementary-test-lab/.venv/lib/python3.10/site-packages/elementary/monitor/api/tests/tests.py", line 55, in _get_test_results_db_rows
    return self.tests_fetcher.get_all_test_results_db_rows(
  File "/Users/emif/Documents/mutt/dbt-elementary-test-lab/.venv/lib/python3.10/site-packages/elementary/monitor/fetchers/tests/tests.py", line 25, in get_all_test_results_db_rows
    run_operation_response = self.dbt_runner.run_operation(
  File "/Users/emif/Documents/mutt/dbt-elementary-test-lab/.venv/lib/python3.10/site-packages/elementary/clients/dbt/command_line_dbt_runner.py", line 177, in run_operation
    result = self._run_command(
  File "/Users/emif/Documents/mutt/dbt-elementary-test-lab/.venv/lib/python3.10/site-packages/elementary/clients/dbt/command_line_dbt_runner.py", line 114, in _run_command
    result = self._inner_run_command(
  File "/Users/emif/Documents/mutt/dbt-elementary-test-lab/.venv/lib/python3.10/site-packages/elementary/clients/dbt/api_dbt_runner.py", line 53, in _inner_run_command
    raise DbtCommandError(
elementary.exceptions.exceptions.DbtCommandError: Failed to run dbt command.
Path '/Users/emif/.dbt' does not exist.
2024-12-16 11:52:13 â€” INFO â€” Running with edr=0.16.1
2024-12-16 11:52:13 â€” DEBUG â€” Running dbt command --log-format json run-operation elementary.log_macro_results --args {"macro_name": "elementary_cli.get_latest_invocation", "macro_args": {}} --project-dir /Users/emif/Documents/mutt/dbt-elementary-test-lab/.venv/lib/python3.10/site-packages/elementary/monitor/dbt_project
[31;20m2024-12-16 11:52:13 â€” ERROR â€” Unable to get the latest invocation: Failed to run dbt command.
Path '/Users/emif/.dbt' does not exist.[0m
2024-12-16 11:52:13 â€” DEBUG â€” Running dbt command --log-format json run-operation elementary.log_macro_results --args {"macro_name": "elementary_cli.get_adapter_type_and_unique_id", "macro_args": {}} --project-dir /Users/emif/Documents/mutt/dbt-elementary-test-lab/.venv/lib/python3.10/site-packages/elementary/monitor/dbt_project
2024-12-16 11:52:13 â€” DEBUG â€” Could not get warehouse info.
Traceback (most recent call last):
  File "/Users/emif/Documents/mutt/dbt-elementary-test-lab/.venv/lib/python3.10/site-packages/elementary/monitor/data_monitoring/data_monitoring.py", line 140, in _get_warehouse_info
    self.internal_dbt_runner.run_operation(
  File "/Users/emif/Documents/mutt/dbt-elementary-test-lab/.venv/lib/python3.10/site-packages/elementary/clients/dbt/command_line_dbt_runner.py", line 177, in run_operation
    result = self._run_command(
  File "/Users/emif/Documents/mutt/dbt-elementary-test-lab/.venv/lib/python3.10/site-packages/elementary/clients/dbt/command_line_dbt_runner.py", line 114, in _run_command
    result = self._inner_run_command(
  File "/Users/emif/Documents/mutt/dbt-elementary-test-lab/.venv/lib/python3.10/site-packages/elementary/clients/dbt/api_dbt_runner.py", line 53, in _inner_run_command
    raise DbtCommandError(
elementary.exceptions.exceptions.DbtCommandError: Failed to run dbt command.
Path '/Users/emif/.dbt' does not exist.
2024-12-16 11:52:13 â€” DEBUG â€” Running dbt command --log-format json run-operation elementary.log_macro_results --args {"macro_name": "elementary_cli.get_elementary_database_and_schema", "macro_args": {}} --project-dir /Users/emif/Documents/mutt/dbt-elementary-test-lab/.venv/lib/python3.10/site-packages/elementary/monitor/dbt_project
[31;20m2024-12-16 11:52:13 â€” ERROR â€” Failed to parse Elementary's database and schema.[0m
2024-12-16 11:52:13 â€” INFO â€” Running dbt command --log-format json run-operation elementary.log_macro_results --args {"macro_name": "elementary_cli.get_test_results", "macro_args": {"days_back": 7, "invocations_per_test": 720, "disable_passed_test_metrics": false}} --project-dir /Users/emif/Documents/mutt/dbt-elementary-test-lab/.venv/lib/python3.10/site-packages/elementary/monitor/dbt_project
[31;20m2024-12-16 11:52:13 â€” ERROR â€” Could not generate the report - Error: Failed to run dbt command.
Path '/Users/emif/.dbt' does not exist.
Please reach out to our community for help with this issue.[0m
Traceback (most recent call last):
  File "/Users/emif/Documents/mutt/dbt-elementary-test-lab/.venv/lib/python3.10/site-packages/elementary/monitor/api/report/report.py", line 50, in get_report_data
    tests_api = TestsAPI(
  File "/Users/emif/Documents/mutt/dbt-elementary-test-lab/.venv/lib/python3.10/site-packages/elementary/monitor/api/tests/tests.py", line 43, in __init__
    self.test_results_db_rows = self._get_test_results_db_rows(
  File "/Users/emif/Documents/mutt/dbt-elementary-test-lab/.venv/lib/python3.10/site-packages/elementary/monitor/api/tests/tests.py", line 55, in _get_test_results_db_rows
    return self.tests_fetcher.get_all_test_results_db_rows(
  File "/Users/emif/Documents/mutt/dbt-elementary-test-lab/.venv/lib/python3.10/site-packages/elementary/monitor/fetchers/tests/tests.py", line 25, in get_all_test_results_db_rows
    run_operation_response = self.dbt_runner.run_operation(
  File "/Users/emif/Documents/mutt/dbt-elementary-test-lab/.venv/lib/python3.10/site-packages/elementary/clients/dbt/command_line_dbt_runner.py", line 177, in run_operation
    result = self._run_command(
  File "/Users/emif/Documents/mutt/dbt-elementary-test-lab/.venv/lib/python3.10/site-packages/elementary/clients/dbt/command_line_dbt_runner.py", line 114, in _run_command
    result = self._inner_run_command(
  File "/Users/emif/Documents/mutt/dbt-elementary-test-lab/.venv/lib/python3.10/site-packages/elementary/clients/dbt/api_dbt_runner.py", line 53, in _inner_run_command
    raise DbtCommandError(
elementary.exceptions.exceptions.DbtCommandError: Failed to run dbt command.
Path '/Users/emif/.dbt' does not exist.
2024-12-16 11:53:07 â€” INFO â€” Running with edr=0.16.1
2024-12-16 11:53:07 â€” DEBUG â€” Running dbt command --log-format json run-operation elementary.log_macro_results --args {"macro_name": "elementary_cli.get_latest_invocation", "macro_args": {}} --project-dir /Users/emif/Documents/mutt/dbt-elementary-test-lab/.venv/lib/python3.10/site-packages/elementary/monitor/dbt_project
[31;20m2024-12-16 11:53:07 â€” ERROR â€” Unable to get the latest invocation: Failed to run dbt command.
Path '/Users/emif/.dbt' does not exist.[0m
2024-12-16 11:53:07 â€” DEBUG â€” Running dbt command --log-format json run-operation elementary.log_macro_results --args {"macro_name": "elementary_cli.get_adapter_type_and_unique_id", "macro_args": {}} --project-dir /Users/emif/Documents/mutt/dbt-elementary-test-lab/.venv/lib/python3.10/site-packages/elementary/monitor/dbt_project
2024-12-16 11:53:07 â€” DEBUG â€” Could not get warehouse info.
Traceback (most recent call last):
  File "/Users/emif/Documents/mutt/dbt-elementary-test-lab/.venv/lib/python3.10/site-packages/elementary/monitor/data_monitoring/data_monitoring.py", line 140, in _get_warehouse_info
    self.internal_dbt_runner.run_operation(
  File "/Users/emif/Documents/mutt/dbt-elementary-test-lab/.venv/lib/python3.10/site-packages/elementary/clients/dbt/command_line_dbt_runner.py", line 177, in run_operation
    result = self._run_command(
  File "/Users/emif/Documents/mutt/dbt-elementary-test-lab/.venv/lib/python3.10/site-packages/elementary/clients/dbt/command_line_dbt_runner.py", line 114, in _run_command
    result = self._inner_run_command(
  File "/Users/emif/Documents/mutt/dbt-elementary-test-lab/.venv/lib/python3.10/site-packages/elementary/clients/dbt/api_dbt_runner.py", line 53, in _inner_run_command
    raise DbtCommandError(
elementary.exceptions.exceptions.DbtCommandError: Failed to run dbt command.
Path '/Users/emif/.dbt' does not exist.
2024-12-16 11:53:07 â€” DEBUG â€” Running dbt command --log-format json run-operation elementary.log_macro_results --args {"macro_name": "elementary_cli.get_elementary_database_and_schema", "macro_args": {}} --project-dir /Users/emif/Documents/mutt/dbt-elementary-test-lab/.venv/lib/python3.10/site-packages/elementary/monitor/dbt_project
[31;20m2024-12-16 11:53:07 â€” ERROR â€” Failed to parse Elementary's database and schema.[0m
2024-12-16 11:53:07 â€” INFO â€” Running dbt command --log-format json run-operation elementary.log_macro_results --args {"macro_name": "elementary_cli.get_test_results", "macro_args": {"days_back": 7, "invocations_per_test": 720, "disable_passed_test_metrics": false}} --project-dir /Users/emif/Documents/mutt/dbt-elementary-test-lab/.venv/lib/python3.10/site-packages/elementary/monitor/dbt_project
[31;20m2024-12-16 11:53:07 â€” ERROR â€” Could not generate the report - Error: Failed to run dbt command.
Path '/Users/emif/.dbt' does not exist.
Please reach out to our community for help with this issue.[0m
Traceback (most recent call last):
  File "/Users/emif/Documents/mutt/dbt-elementary-test-lab/.venv/lib/python3.10/site-packages/elementary/monitor/api/report/report.py", line 50, in get_report_data
    tests_api = TestsAPI(
  File "/Users/emif/Documents/mutt/dbt-elementary-test-lab/.venv/lib/python3.10/site-packages/elementary/monitor/api/tests/tests.py", line 43, in __init__
    self.test_results_db_rows = self._get_test_results_db_rows(
  File "/Users/emif/Documents/mutt/dbt-elementary-test-lab/.venv/lib/python3.10/site-packages/elementary/monitor/api/tests/tests.py", line 55, in _get_test_results_db_rows
    return self.tests_fetcher.get_all_test_results_db_rows(
  File "/Users/emif/Documents/mutt/dbt-elementary-test-lab/.venv/lib/python3.10/site-packages/elementary/monitor/fetchers/tests/tests.py", line 25, in get_all_test_results_db_rows
    run_operation_response = self.dbt_runner.run_operation(
  File "/Users/emif/Documents/mutt/dbt-elementary-test-lab/.venv/lib/python3.10/site-packages/elementary/clients/dbt/command_line_dbt_runner.py", line 177, in run_operation
    result = self._run_command(
  File "/Users/emif/Documents/mutt/dbt-elementary-test-lab/.venv/lib/python3.10/site-packages/elementary/clients/dbt/command_line_dbt_runner.py", line 114, in _run_command
    result = self._inner_run_command(
  File "/Users/emif/Documents/mutt/dbt-elementary-test-lab/.venv/lib/python3.10/site-packages/elementary/clients/dbt/api_dbt_runner.py", line 53, in _inner_run_command
    raise DbtCommandError(
elementary.exceptions.exceptions.DbtCommandError: Failed to run dbt command.
Path '/Users/emif/.dbt' does not exist.
2024-12-16 11:53:30 â€” INFO â€” Running with edr=0.16.1
2024-12-16 11:53:30 â€” DEBUG â€” Running dbt command --log-format json run-operation elementary.log_macro_results --args {"macro_name": "elementary_cli.get_latest_invocation", "macro_args": {}} --project-dir /Users/emif/Documents/mutt/dbt-elementary-test-lab/.venv/lib/python3.10/site-packages/elementary/monitor/dbt_project
[31;20m2024-12-16 11:53:30 â€” ERROR â€” Unable to get the latest invocation: Failed to run dbt command.
Path '/Users/emif/.dbt' does not exist.[0m
2024-12-16 11:53:30 â€” DEBUG â€” Running dbt command --log-format json run-operation elementary.log_macro_results --args {"macro_name": "elementary_cli.get_adapter_type_and_unique_id", "macro_args": {}} --project-dir /Users/emif/Documents/mutt/dbt-elementary-test-lab/.venv/lib/python3.10/site-packages/elementary/monitor/dbt_project
2024-12-16 11:53:30 â€” DEBUG â€” Could not get warehouse info.
Traceback (most recent call last):
  File "/Users/emif/Documents/mutt/dbt-elementary-test-lab/.venv/lib/python3.10/site-packages/elementary/monitor/data_monitoring/data_monitoring.py", line 140, in _get_warehouse_info
    self.internal_dbt_runner.run_operation(
  File "/Users/emif/Documents/mutt/dbt-elementary-test-lab/.venv/lib/python3.10/site-packages/elementary/clients/dbt/command_line_dbt_runner.py", line 177, in run_operation
    result = self._run_command(
  File "/Users/emif/Documents/mutt/dbt-elementary-test-lab/.venv/lib/python3.10/site-packages/elementary/clients/dbt/command_line_dbt_runner.py", line 114, in _run_command
    result = self._inner_run_command(
  File "/Users/emif/Documents/mutt/dbt-elementary-test-lab/.venv/lib/python3.10/site-packages/elementary/clients/dbt/api_dbt_runner.py", line 53, in _inner_run_command
    raise DbtCommandError(
elementary.exceptions.exceptions.DbtCommandError: Failed to run dbt command.
Path '/Users/emif/.dbt' does not exist.
2024-12-16 11:53:30 â€” DEBUG â€” Running dbt command --log-format json run-operation elementary.log_macro_results --args {"macro_name": "elementary_cli.get_elementary_database_and_schema", "macro_args": {}} --project-dir /Users/emif/Documents/mutt/dbt-elementary-test-lab/.venv/lib/python3.10/site-packages/elementary/monitor/dbt_project
[31;20m2024-12-16 11:53:30 â€” ERROR â€” Failed to parse Elementary's database and schema.[0m
2024-12-16 11:53:30 â€” INFO â€” Running dbt command --log-format json run-operation elementary.log_macro_results --args {"macro_name": "elementary_cli.get_test_results", "macro_args": {"days_back": 7, "invocations_per_test": 720, "disable_passed_test_metrics": false}} --project-dir /Users/emif/Documents/mutt/dbt-elementary-test-lab/.venv/lib/python3.10/site-packages/elementary/monitor/dbt_project
[31;20m2024-12-16 11:53:30 â€” ERROR â€” Could not generate the report - Error: Failed to run dbt command.
Path '/Users/emif/.dbt' does not exist.
Please reach out to our community for help with this issue.[0m
Traceback (most recent call last):
  File "/Users/emif/Documents/mutt/dbt-elementary-test-lab/.venv/lib/python3.10/site-packages/elementary/monitor/api/report/report.py", line 50, in get_report_data
    tests_api = TestsAPI(
  File "/Users/emif/Documents/mutt/dbt-elementary-test-lab/.venv/lib/python3.10/site-packages/elementary/monitor/api/tests/tests.py", line 43, in __init__
    self.test_results_db_rows = self._get_test_results_db_rows(
  File "/Users/emif/Documents/mutt/dbt-elementary-test-lab/.venv/lib/python3.10/site-packages/elementary/monitor/api/tests/tests.py", line 55, in _get_test_results_db_rows
    return self.tests_fetcher.get_all_test_results_db_rows(
  File "/Users/emif/Documents/mutt/dbt-elementary-test-lab/.venv/lib/python3.10/site-packages/elementary/monitor/fetchers/tests/tests.py", line 25, in get_all_test_results_db_rows
    run_operation_response = self.dbt_runner.run_operation(
  File "/Users/emif/Documents/mutt/dbt-elementary-test-lab/.venv/lib/python3.10/site-packages/elementary/clients/dbt/command_line_dbt_runner.py", line 177, in run_operation
    result = self._run_command(
  File "/Users/emif/Documents/mutt/dbt-elementary-test-lab/.venv/lib/python3.10/site-packages/elementary/clients/dbt/command_line_dbt_runner.py", line 114, in _run_command
    result = self._inner_run_command(
  File "/Users/emif/Documents/mutt/dbt-elementary-test-lab/.venv/lib/python3.10/site-packages/elementary/clients/dbt/api_dbt_runner.py", line 53, in _inner_run_command
    raise DbtCommandError(
elementary.exceptions.exceptions.DbtCommandError: Failed to run dbt command.
Path '/Users/emif/.dbt' does not exist.
